Workbook

Sheet Despre
A1: Timpul precesional uman și calendarul precesional uman
A2: Un sistem de timp și de dată construit numai pe ce poate observa orice om de pe Pământ, fără nicio doctrină.
A3: Ziua este o rotație completă a Pământului, de 360° și 36 de ore noi (1 oră nouă = 10°, 1 minut nou = 1°, 1 secundă nouă = 0,1°, 1 subsecundă = o secundă SI).
A4: Anul pornește de la solstițiul din decembrie. Soarele și Luna sunt calculate după poziția lor reală pe cer; calendarul are 13 luni × 28 de zile.
A5: Cea mai lentă mișcare, precesia echinocțiilor (25.772 de ani), împarte timpul în 12 ere precesionale (ER) cu ani ai erei (AE).
A6: Un singur ciclu cuprinde toată istoria cunoscută a omenirii, de la artele rupestre până în anul 2440, deci orice dată din trecut are un cod unic. După 2440 începe ciclul următor.
A7: Variante de precesie luate în calcul: (A) limite reale ale erelor, (B) ere egale cu ciclu reglat, (C) ere egale, modelul actual. S-a ales C, pentru simplitate.
A8: Foile: Timp 36h, Conversie, Fusuri noi (timpul); Timp complet, Ere, Luni noi, Evenimente (data); Calendar 13 luni, Calendar an, Calendar perete (calendarul); Nume sanscrită, Nume EN-FR, Cadrane.

Sheet Timp 36h
A1: Ora (0-35) | B1: Minutul (0-9) | C1: Secunda (0-9) | D1: Unghi de rotație (°) | E1: Echivalent timp standard | G1: Reguli folosite (date de utilizator)
A2: =INT((ROW()-2)/100) -> 0 | B2: =MOD(INT((ROW()-2)/10),10) -> 0 | C2: =MOD(ROW()-2,10) -> 0 | D2: =A2*10+B2+C2/10 -> 0 | E2: =ROUND((ROW()-2)*24,0)/86400 -> 0 | G2: 1 rotație completă = 360° = 36 de ore noi
A3: =INT((ROW()-2)/100) -> 0 | B3: =MOD(INT((ROW()-2)/10),10) -> 0 | C3: =MOD(ROW()-2,10) -> 1 | D3: =A3*10+B3+C3/10 -> 0.1 | E3: =ROUND((ROW()-2)*24,0)/86400 -> 0.00027777778 | G3: 1 oră nouă = 10° = 10 minute noi
A4: =INT((ROW()-2)/100) -> 0 | B4: =MOD(INT((ROW()-2)/10),10) -> 0 | C4: =MOD(ROW()-2,10) -> 2 | D4: =A4*10+B4+C4/10 -> 0.2 | E4: =ROUND((ROW()-2)*24,0)/86400 -> 0.00055555556 | G4: 1 minut nou = 1° = 10 secunde noi
A5: =INT((ROW()-2)/100) -> 0 | B5: =MOD(INT((ROW()-2)/10),10) -> 0 | C5: =MOD(ROW()-2,10) -> 3 | D5: =A5*10+B5+C5/10 -> 0.3 | E5: =ROUND((ROW()-2)*24,0)/86400 -> 0.00083333333 | G5: 1 secundă nouă = 0,1°
A6: =INT((ROW()-2)/100) -> 0 | B6: =MOD(INT((ROW()-2)/10),10) -> 0 | C6: =MOD(ROW()-2,10) -> 4 | D6: =A6*10+B6+C6/10 -> 0.4 | E6: =ROUND((ROW()-2)*24,0)/86400 -> 0.0011111111 | G6: Total: 36 × 10 × 10 = 3.600 secunde noi pe rotație (rândurile 2-3601)
A7: =INT((ROW()-2)/100) -> 0 | B7: =MOD(INT((ROW()-2)/10),10) -> 0 | C7: =MOD(ROW()-2,10) -> 5 | D7: =A7*10+B7+C7/10 -> 0.5 | E7: =ROUND((ROW()-2)*24,0)/86400 -> 0.0013888889
A8: =INT((ROW()-2)/100) -> 0 | B8: =MOD(INT((ROW()-2)/10),10) -> 0 | C8: =MOD(ROW()-2,10) -> 6 | D8: =A8*10+B8+C8/10 -> 0.6 | E8: =ROUND((ROW()-2)*24,0)/86400 -> 0.0016666667 | G8: Echivalențe (presupunere: o rotație = o zi standard de 24 h)
A9: =INT((ROW()-2)/100) -> 0 | B9: =MOD(INT((ROW()-2)/10),10) -> 0 | C9: =MOD(ROW()-2,10) -> 7 | D9: =A9*10+B9+C9/10 -> 0.7 | E9: =ROUND((ROW()-2)*24,0)/86400 -> 0.0019444444 | G9: 1 oră nouă = 40 minute standard
A10: =INT((ROW()-2)/100) -> 0 | B10: =MOD(INT((ROW()-2)/10),10) -> 0 | C10: =MOD(ROW()-2,10) -> 8 | D10: =A10*10+B10+C10/10 -> 0.8 | E10: =ROUND((ROW()-2)*24,0)/86400 -> 0.0022222222 | G10: 1 minut nou = 4 minute standard
A11: =INT((ROW()-2)/100) -> 0 | B11: =MOD(INT((ROW()-2)/10),10) -> 0 | C11: =MOD(ROW()-2,10) -> 9 | D11: =A11*10+B11+C11/10 -> 0.9 | E11: =ROUND((ROW()-2)*24,0)/86400 -> 0.0025 | G11: 1 secundă nouă = 24 secunde standard
A12: =INT((ROW()-2)/100) -> 0 | B12: =MOD(INT((ROW()-2)/10),10) -> 1 | C12: =MOD(ROW()-2,10) -> 0 | D12: =A12*10+B12+C12/10 -> 1 | E12: =ROUND((ROW()-2)*24,0)/86400 -> 0.0027777778 | G12: Simplificare: Pământul face 360° într-o zi siderală (23 h 56 min 4 s); aici s-a folosit ziua de 24 h.
A13: =INT((ROW()-2)/100) -> 0 | B13: =MOD(INT((ROW()-2)/10),10) -> 1 | C13: =MOD(ROW()-2,10) -> 1 | D13: =A13*10+B13+C13/10 -> 1.1 | E13: =ROUND((ROW()-2)*24,0)/86400 -> 0.0030555556
A14: =INT((ROW()-2)/100) -> 0 | B14: =MOD(INT((ROW()-2)/10),10) -> 1 | C14: =MOD(ROW()-2,10) -> 2 | D14: =A14*10+B14+C14/10 -> 1.2 | E14: =ROUND((ROW()-2)*24,0)/86400 -> 0.0033333333
A15: =INT((ROW()-2)/100) -> 0 | B15: =MOD(INT((ROW()-2)/10),10) -> 1 | C15: =MOD(ROW()-2,10) -> 3 | D15: =A15*10+B15+C15/10 -> 1.3 | E15: =ROUND((ROW()-2)*24,0)/86400 -> 0.0036111111
A16: =INT((ROW()-2)/100) -> 0 | B16: =MOD(INT((ROW()-2)/10),10) -> 1 | C16: =MOD(ROW()-2,10) -> 4 | D16: =A16*10+B16+C16/10 -> 1.4 | E16: =ROUND((ROW()-2)*24,0)/86400 -> 0.0038888889
A17: =INT((ROW()-2)/100) -> 0 | B17: =MOD(INT((ROW()-2)/10),10) -> 1 | C17: =MOD(ROW()-2,10) -> 5 | D17: =A17*10+B17+C17/10 -> 1.5 | E17: =ROUND((ROW()-2)*24,0)/86400 -> 0.0041666667
A18: =INT((ROW()-2)/100) -> 0 | B18: =MOD(INT((ROW()-2)/10),10) -> 1 | C18: =MOD(ROW()-2,10) -> 6 | D18: =A18*10+B18+C18/10 -> 1.6 | E18: =ROUND((ROW()-2)*24,0)/86400 -> 0.0044444444
A19: =INT((ROW()-2)/100) -> 0 | B19: =MOD(INT((ROW()-2)/10),10) -> 1 | C19: =MOD(ROW()-2,10) -> 7 | D19: =A19*10+B19+C19/10 -> 1.7 | E19: =ROUND((ROW()-2)*24,0)/86400 -> 0.0047222222
A20: =INT((ROW()-2)/100) -> 0 | B20: =MOD(INT((ROW()-2)/10),10) -> 1 | C20: =MOD(ROW()-2,10) -> 8 | D20: =A20*10+B20+C20/10 -> 1.8 | E20: =ROUND((ROW()-2)*24,0)/86400 -> 0.005
A21: =INT((ROW()-2)/100) -> 0 | B21: =MOD(INT((ROW()-2)/10),10) -> 1 | C21: =MOD(ROW()-2,10) -> 9 | D21: =A21*10+B21+C21/10 -> 1.9 | E21: =ROUND((ROW()-2)*24,0)/86400 -> 0.0052777778
A22: =INT((ROW()-2)/100) -> 0 | B22: =MOD(INT((ROW()-2)/10),10) -> 2 | C22: =MOD(ROW()-2,10) -> 0 | D22: =A22*10+B22+C22/10 -> 2 | E22: =ROUND((ROW()-2)*24,0)/86400 -> 0.0055555556
A23: =INT((ROW()-2)/100) -> 0 | B23: =MOD(INT((ROW()-2)/10),10) -> 2 | C23: =MOD(ROW()-2,10) -> 1 | D23: =A23*10+B23+C23/10 -> 2.1 | E23: =ROUND((ROW()-2)*24,0)/86400 -> 0.0058333333
A24: =INT((ROW()-2)/100) -> 0 | B24: =MOD(INT((ROW()-2)/10),10) -> 2 | C24: =MOD(ROW()-2,10) -> 2 | D24: =A24*10+B24+C24/10 -> 2.2 | E24: =ROUND((ROW()-2)*24,0)/86400 -> 0.0061111111
... A3601: =INT((ROW()-2)/100) -> 35 | B3601: =MOD(INT((ROW()-2)/10),10) -> 9 | C3601: =MOD(ROW()-2,10) -> 9 | D3601: =A3601*10+B3601+C3601/10 -> 359.9 | E3601: =ROUND((ROW()-2)*24,0)/86400 -> 0.99972222

Sheet Conversie
A1: Timpul precesional uman — Conversie între sistemul internațional (24 h) și sistemul de 36 de ore, cu subsecundă
A2: Completați doar celulele galbene (text albastru). Restul se calculează automat. Toate valorile sunt numere întregi.
A4: 1. Sistem internațional (24 h) → sistem de 36 de ore
B5: Ora (0-23) | C5: Minutele (0-59) | D5: Secundele (0-59)
A6: Timp standard (24 h) - de introdus | B6: 15 | C6: 30 | D6: 45
A7: Secunde standard totale (= subsecunde totale) | B7: =B6*3600+C6*60+D6 -> 55845
B8: Ora (0-35) | C8: Minutul (0-9) | D8: Secunda (0-9) | E8: Subsecunda (0-23) | F8: Unghi de rotație (°)
A9: Timp în sistemul de 36 de ore | B9: =INT(B7/2400) -> 23 | C9: =INT(MOD(B7,2400)/240) -> 2 | D9: =INT(MOD(B7,240)/24) -> 6 | E9: =MOD(B7,24) -> 21 | F9: =B7/240 -> 232.6875
A12: 2. Sistem de 36 de ore → sistem internațional (24 h)
B13: Ora (0-35) | C13: Minutul (0-9) | D13: Secunda (0-9) | E13: Subsecunda (0-23)
A14: Timp în sistemul de 36 de ore - de introdus | B14: 20 | C14: 7 | D14: 5 | E14: 12
A15: Secunde standard totale (= subsecunde totale) | B15: =B14*2400+C14*240+D14*24+E14 -> 49812
B16: Ora (0-23) | C16: Minutele (0-59) | D16: Secundele (0-59) | E16: Format hh:mm:ss
A17: Timp standard (24 h) | B17: =INT(B15/3600) -> 13 | C17: =INT(MOD(B15,3600)/60) -> 50 | D17: =MOD(B15,60) -> 12 | E17: =TEXT(B17,"00")&":"&TEXT(C17,"00")&":"&TEXT(D17,"00") -> 13:50:12
A20: Unitățile sistemului de 36 de ore
A21: Subsecunde pe o secundă nouă (ipoteză) | B21: 24
A22: Grade de rotație pe o secundă nouă (regula 1 s = 0,1°) | B22: 0.1
A23: Unitate | B23: Subsecunde | C23: Secunde standard | D23: Unghi de rotație (°)
A24: Subsecundă | B24: =1 -> 1 | C24: =B24 -> 1 | D24: =B24/$B$21*$B$22 -> 0.0041666667
A25: Secundă nouă | B25: =B21 -> 24 | C25: =B25 -> 24 | D25: =B25/$B$21*$B$22 -> 0.1
A26: Minut nou (10 secunde) | B26: =B25*10 -> 240 | C26: =B26 -> 240 | D26: =B26/$B$21*$B$22 -> 1
A27: Oră nouă (10 minute) | B27: =B26*10 -> 2400 | C27: =B27 -> 2400 | D27: =B27/$B$21*$B$22 -> 10
A28: Zi (36 de ore) | B28: =B27*36 -> 86400 | C28: =B28 -> 86400 | D28: =B28/$B$21*$B$22 -> 360
A31: Puncte de reper (ora standard → ora nouă)
A32: Ora standard (24 h) | B32: Ora nouă (36 h) | C32: Unghi de rotație (°)
A33: 0 | B33: =A33*36/24 -> 0 | C33: =B33*10 -> 0
A34: 3 | B34: =A34*36/24 -> 4.5 | C34: =B34*10 -> 45
A35: 6 | B35: =A35*36/24 -> 9 | C35: =B35*10 -> 90
A36: 9 | B36: =A36*36/24 -> 13.5 | C36: =B36*10 -> 135
A37: 12 | B37: =A37*36/24 -> 18 | C37: =B37*10 -> 180
A38: 15 | B38: =A38*36/24 -> 22.5 | C38: =B38*10 -> 225
A39: 18 | B39: =A39*36/24 -> 27 | C39: =B39*10 -> 270
A40: 21 | B40: =A40*36/24 -> 31.5 | C40: =B40*10 -> 315
A41: 24 | B41: =A41*36/24 -> 36 | C41: =B41*10 -> 360
A44: Reguli și presupuneri
A45: O zi = 24 h standard = 36 h noi = 360° (regulile date de utilizator: 1 h nouă = 10° = 10 minute; 1 minut nou = 1° = 10 secunde; 1 s nouă = 0,1°).
A46: Subsecunda este a 24-a parte dintr-o secundă nouă, deci 1 subsecundă = exact 1 secundă standard (SI). Toate conversiile sunt astfel exacte.
A47: O zi are 3.600 s noi = 86.400 subsecunde = 86.400 s standard. Ora 24 (standard) = ora 36 (nouă) = ora 0 a zilei următoare.
A48: Simplificare: 360° corespund unei zile de 24 h (nu zilei siderale de 23 h 56 min 4 s).

Sheet Calendar 13 luni
A1: Calendarul precesional uman — Calendar de 13 luni × 28 de zile, aliniat la solstițiul din decembrie: conversie gregorian ↔ 13 luni
A2: Completați doar celulele galbene (text albastru). Parametrii sunt în foaia „Timp complet”, la sfârșit.
A4: 1. Data gregoriană → calendar de 13 luni
B5: Data gregoriană
A6: Data gregoriană - de introdus | B6: 46294
A7: Anul nou estimat | B7: =INT((B6-'Timp complet'!$B$45)/'Timp complet'!$B$49)+1 -> 15
A8: Numărul anului nou k (contor intern; k = 1 începe la 22.12.2011) | B8: =B7+IF(B6>=('Timp complet'!$B$45+'Timp complet'!$B$46*(B7)+INT((B7)/'Timp complet'!$B$47)-INT((B7)/'Timp complet'!$B$48)),1,IF(B6<('Timp complet'!$B$45+'Timp complet'!$B$46*(B7-1)+INT((B7-1)/'Timp complet'!$B$47)-INT((B7-1)/'Timp complet'!$B$48)),-1,0)) -> 15
A9: Începutul anului nou (data gregoriană) | B9: =('Timp complet'!$B$45+'Timp complet'!$B$46*(B8-1)+INT((B8-1)/'Timp complet'!$B$47)-INT((B8-1)/'Timp complet'!$B$48)) -> 46012
A10: Ziua din an N (1-366) | B10: =B6-B9+1 -> 283
A11: An nou bisect (366 zile)? | B11: =IF(AND(MOD(B8,'Timp complet'!$B$47)=0,MOD(B8,'Timp complet'!$B$48)<>0),"Da","Nu") -> Nu
B12: ER | C12: AE | D12: Era (sanscrită · engleză · franceză)
A13: Era și anul erei | B13: =ROUNDUP('Timp complet'!$B$51*(MOD(B8-('Timp complet'!$B$52-YEAR('Timp complet'!$B$45)),'Timp complet'!$B$50)+1)/'Timp complet'!$B$50,0) -> 12 | C13: =MOD(B8-('Timp complet'!$B$52-YEAR('Timp complet'!$B$45)),'Timp complet'!$B$50)-INT((B13-1)*'Timp complet'!$B$50/'Timp complet'!$B$51)+1 -> 1734 | D13: =INDEX(Ere!$B$5:$B$16,B13) & " · " & INDEX(Ere!$C$5:$C$16,B13) & " · " & INDEX(Ere!$D$5:$D$16,B13) -> Mīna · Pisces · Poissons
B14: Luna (1-13) | C14: Ziua lunii (1-28) | D14: Ziua săptămânii | E14: Săptămâna (1-52) | F14: Tip zi
A15: Data în calendarul de 13 luni | B15: =IF($B$10<='Timp complet'!$B$60,INT(($B$10-1)/'Timp complet'!$B$58)+1,"-") -> 11 | C15: =IF($B$10<='Timp complet'!$B$60,MOD($B$10-1,'Timp complet'!$B$58)+1,"-") -> 3 | D15: =IF($B$10<='Timp complet'!$B$60,INDEX('Nume sanscrită'!$B$21:$B$27,MOD($B$10-1,7)+1),"-") -> Miercuri | E15: =IF($B$10<='Timp complet'!$B$60,INT(($B$10-1)/7)+1,"-") -> 41 | F15: =IF($B$10<='Timp complet'!$B$60,"Zi obișnuită",IF($B$10='Timp complet'!$B$60+1,"Ziua anului","Ziua bisectă")) -> Zi obișnuită
B16: Luna (sanscrită) | C16: Ziua săptămânii (sanscrită) | D16: Arcul solar (AS) | E16: Ziua din arc (ZA) | F16: Cadranul solar (CS)
A17: Denumiri sanscrite și arcul solar | B17: =IF($B$10<='Timp complet'!$B$60,INDEX('Nume sanscrită'!$F$5:$F$17,B15),IF($B$10='Timp complet'!$B$60+1,'Nume sanscrită'!$B$31,'Nume sanscrită'!$B$32)) -> Ekādaśa māsa | C17: =IF($B$10<='Timp complet'!$B$60,INDEX('Nume sanscrită'!$C$21:$C$27,MOD($B$10-1,7)+1),"-") -> Budhavāra | D17: =MIN('Timp complet'!$B$54,INT(($B$10-1)/'Timp complet'!$B$53)+1) -> 57 | E17: =$B$10-'Timp complet'!$B$53*(D17-1) -> 3 | F17: =INDEX(Evenimente!$G$2:$G$1213,MATCH($B$6+1,Evenimente!$F$2:$F$1213,1)) -> 4
A20: 2. Calendar de 13 luni → data gregoriană
B21: An gregorian (identifică anul nou) | C21: Luna (1-13) | D21: Ziua lunii (1-28) | E21: Zi specială
A22: Data în calendarul de 13 luni - de introdus | B22: 2026 | C22: 11 | D22: 3 | E22: Nu
A23: Anul nou estimat | B23: =INT((DATE(B22,7,1)-'Timp complet'!$B$45)/'Timp complet'!$B$49)+1 -> 15
A24: Numărul anului nou k (cel care conține 1 iulie al anului ales) | B24: =B23+IF(DATE(B22,7,1)>=('Timp complet'!$B$45+'Timp complet'!$B$46*(B23)+INT((B23)/'Timp complet'!$B$47)-INT((B23)/'Timp complet'!$B$48)),1,IF(DATE(B22,7,1)<('Timp complet'!$B$45+'Timp complet'!$B$46*(B23-1)+INT((B23-1)/'Timp complet'!$B$47)-INT((B23-1)/'Timp complet'!$B$48)),-1,0)) -> 15
A25: Începutul anului nou | B25: =('Timp complet'!$B$45+'Timp complet'!$B$46*(B24-1)+INT((B24-1)/'Timp complet'!$B$47)-INT((B24-1)/'Timp complet'!$B$48)) -> 46012
A26: Ziua din an N | B26: =IF(E22="Ziua anului",'Timp complet'!$B$60+1,IF(E22="Ziua bisectă",'Timp complet'!$B$60+2,(C22-1)*'Timp complet'!$B$58+D22)) -> 283
A27: An nou bisect (366 zile)? | B27: =IF(AND(MOD(B24,'Timp complet'!$B$47)=0,MOD(B24,'Timp complet'!$B$48)<>0),"Da","Nu") -> Nu
B28: Data gregoriană | C28: Ziua săptămânii (gregoriană) | D28: Ziua săptămânii (calendar nou)
A29: Data gregoriană | B29: =IF(AND(B26='Timp complet'!$B$60+2,B27="Nu"),"An nebisect",B25+B26-1) -> 46294 | C29: =IF(ISNUMBER(B29),INDEX('Nume sanscrită'!$B$21:$B$27,WEEKDAY(B29,2)),"-") -> Marți | D29: =IF(B26<='Timp complet'!$B$60,INDEX('Nume sanscrită'!$B$21:$B$27,MOD(B26-1,7)+1),"-") -> Miercuri
A30: Pentru Ziua anului sau Ziua bisectă, alegeți-o în coloana „Zi specială”; luna și ziua sunt ignorate.
A32: 3. Cele 13 luni ale anului nou ales, cu datele gregoriene
A33: An gregorian - de introdus (anul nou care conține 1 iulie) | B33: 2026
A34: Anul nou estimat | B34: =INT((DATE(B33,7,1)-'Timp complet'!$B$45)/'Timp complet'!$B$49)+1 -> 15
A35: Numărul anului nou k | B35: =B34+IF(DATE(B33,7,1)>=('Timp complet'!$B$45+'Timp complet'!$B$46*(B34)+INT((B34)/'Timp complet'!$B$47)-INT((B34)/'Timp complet'!$B$48)),1,IF(DATE(B33,7,1)<('Timp complet'!$B$45+'Timp complet'!$B$46*(B34-1)+INT((B34-1)/'Timp complet'!$B$47)-INT((B34-1)/'Timp complet'!$B$48)),-1,0)) -> 15
A36: Începutul anului nou (ziua solstițiului) | B36: =('Timp complet'!$B$45+'Timp complet'!$B$46*(B35-1)+INT((B35-1)/'Timp complet'!$B$47)-INT((B35-1)/'Timp complet'!$B$48)) -> 46012
A37: Sfârșitul anului nou | B37: =('Timp complet'!$B$45+'Timp complet'!$B$46*(B35)+INT((B35)/'Timp complet'!$B$47)-INT((B35)/'Timp complet'!$B$48))-1 -> 46376
A38: Zile în anul nou | B38: =B37-B36+1 -> 365
A39: ER-AE | B39: =ROUNDUP('Timp complet'!$B$51*(MOD(B35-('Timp complet'!$B$52-YEAR('Timp complet'!$B$45)),'Timp complet'!$B$50)+1)/'Timp complet'!$B$50,0)&"-"&TEXT(MOD(B35-('Timp complet'!$B$52-YEAR('Timp complet'!$B$45)),'Timp complet'!$B$50)-INT((ROUNDUP('Timp complet'!$B$51*(MOD(B35-('Timp complet'!$B$52-YEAR('Timp complet'!$B$45)),'Timp complet'!$B$50)+1)/'Timp complet'!$B$50,0)-1)*'Timp complet'!$B$50/'Timp complet'!$B$51)+1,"0000") -> 12-1734
A40: Luna | B40: Nume (sanscrită) | C40: Prima zi (gregorian) | D40: Ultima zi (gregorian) | E40: Zile
A41: 1 | B41: =INDEX('Nume sanscrită'!$F$5:$F$17,A41) -> Prathama māsa | C41: =$B$36+(A41-1)*'Timp complet'!$B$58 -> 46012 | D41: =C41+'Timp complet'!$B$58-1 -> 46039 | E41: ='Timp complet'!$B$58 -> 28
A42: 2 | B42: =INDEX('Nume sanscrită'!$F$5:$F$17,A42) -> Dvitīya māsa | C42: =$B$36+(A42-1)*'Timp complet'!$B$58 -> 46040 | D42: =C42+'Timp complet'!$B$58-1 -> 46067 | E42: ='Timp complet'!$B$58 -> 28
A43: 3 | B43: =INDEX('Nume sanscrită'!$F$5:$F$17,A43) -> Tṛtīya māsa | C43: =$B$36+(A43-1)*'Timp complet'!$B$58 -> 46068 | D43: =C43+'Timp complet'!$B$58-1 -> 46095 | E43: ='Timp complet'!$B$58 -> 28
A44: 4 | B44: =INDEX('Nume sanscrită'!$F$5:$F$17,A44) -> Caturtha māsa | C44: =$B$36+(A44-1)*'Timp complet'!$B$58 -> 46096 | D44: =C44+'Timp complet'!$B$58-1 -> 46123 | E44: ='Timp complet'!$B$58 -> 28
...

Sheet Calendar an
A1: Calendarul precesional uman — Calendarul de 13 luni, zi cu zi, pentru anul nou ales (începe la solstițiul din decembrie)
A2: An gregorian (din foaia „Calendar 13 luni”, celula B33) | B2: ='Calendar 13 luni'!B33 -> 2026 | D2: Zile în an: | E2: ='Calendar 13 luni'!B38 -> 365
A3: Anul nou începe la (ziua solstițiului) | B3: ='Calendar 13 luni'!B36 -> 46012 | D3: ER-AE: | E3: ='Calendar 13 luni'!B39 -> 12-1734
A4: Data gregoriană | B4: Ziua din an | C4: Luna (1-13) | D4: Ziua lunii (1-28) | E4: Ziua săptămânii (calendar nou) | F4: Ziua săptămânii (gregoriană) | G4: Arc solar (AS) | H4: Cadran solar (CS) | I4: Fenomen astronomic (UTC)
A5: =IF(B5="","",$B$3+B5-1) -> 46012 | B5: =IF(ROW()-4<=$E$2,ROW()-4,"") -> 1 | C5: =IF(B5="","",IF(B5<='Timp complet'!$B$60,INT((B5-1)/'Timp complet'!$B$58)+1,IF(B5='Timp complet'!$B$60+1,"Ziua anului","Ziua bisectă"))) -> 1 | D5: =IF(B5="","",IF(B5<='Timp complet'!$B$60,MOD(B5-1,'Timp complet'!$B$58)+1,"-")) -> 1 | E5: =IF(B5="","",IF(B5<='Timp complet'!$B$60,INDEX('Nume sanscrită'!$B$21:$B$27,MOD(B5-1,7)+1),"-")) -> Luni | F5: =IF(B5="","",INDEX('Nume sanscrită'!$B$21:$B$27,WEEKDAY(A5,2))) -> Duminică | G5: =IF(B5="","",MIN('Timp complet'!$B$54,INT((B5-1)/'Timp complet'!$B$53)+1)) -> 1 | H5: =IF(B5="","",INDEX(Evenimente!$G$2:$G$1213,MATCH(A5+1,Evenimente!$F$2:$F$1213,1))) -> 1 | I5: =IF(B5="","",IF(INDEX(Evenimente!$A$2:$A$16203,MATCH(A5-0.000001,Evenimente!$A$2:$A$16203,1)+1)<A5+1,INDEX(Evenimente!$B$2:$B$16203,MATCH(A5-0.000001,Evenimente!$A$2:$A$16203,1)+1)&" "&INDEX(Evenimente!$C$2:$C$16203,MATCH(A5-0.000001,Evenimente!$A$2:$A$16203,1)+1)&" "&TEXT(HOUR(INDEX(Evenimente!$A$2:$A$16203,MATCH(A5-0.000001,Evenimente!$A$2:$A$16203,1)+1)),"00")&":"&TEXT(MINUTE(INDEX(Evenimente!$A$2:$A$16203,MATCH(A5-0.000001,Evenimente!$A$2:$A$16203,1)+1)),"00")&" UTC"&IF(INDEX(Evenimente!$A$2:$A$16203,MATCH(A5-0.000001,Evenimente!$A$2:$A$16203,1)+2)<A5+1,"; "&INDEX(Evenimente!$B$2:$B$16203,MATCH(A5-0.000001,Evenimente!$A$2:$A$16203,1)+2)&" "&INDEX(Evenimente!$C$2:$C$16203,MATCH(A5-0.000001,Evenimente!$A$2:$A$16203,1)+2)&" "&TEXT(HOUR(INDEX(Evenimente!$A$2:$A$16203,MATCH(A5-0.000001,Evenimente!$A$2:$A$16203,1)+2)),"00")&":"&TEXT(MINUTE(INDEX(Evenimente!$A$2:$A$16203,MATCH(A5-0.000001,Evenimente!$A$2:$A$16203,1)+2)),"00")&" UTC",""),"")) -> ☀ solstițiul din decembrie 15:03 UTC
A6: =IF(B6="","",$B$3+B6-1) -> 46013 | B6: =IF(ROW()-4<=$E$2,ROW()-4,"") -> 2 | C6: =IF(B6="","",IF(B6<='Timp complet'!$B$60,INT((B6-1)/'Timp complet'!$B$58)+1,IF(B6='Timp complet'!$B$60+1,"Ziua anului","Ziua bisectă"))) -> 1 | D6: =IF(B6="","",IF(B6<='Timp complet'!$B$60,MOD(B6-1,'Timp complet'!$B$58)+1,"-")) -> 2 | E6: =IF(B6="","",IF(B6<='Timp complet'!$B$60,INDEX('Nume sanscrită'!$B$21:$B$27,MOD(B6-1,7)+1),"-")) -> Marți | F6: =IF(B6="","",INDEX('Nume sanscrită'!$B$21:$B$27,WEEKDAY(A6,2))) -> Luni | G6: =IF(B6="","",MIN('Timp complet'!$B$54,INT((B6-1)/'Timp complet'!$B$53)+1)) -> 1 | H6: =IF(B6="","",INDEX(Evenimente!$G$2:$G$1213,MATCH(A6+1,Evenimente!$F$2:$F$1213,1))) -> 1 | I6: =IF(B6="","",IF(INDEX(Evenimente!$A$2:$A$16203,MATCH(A6-0.000001,Evenimente!$A$2:$A$16203,1)+1)<A6+1,INDEX(Evenimente!$B$2:$B$16203,MATCH(A6-0.000001,Evenimente!$A$2:$A$16203,1)+1)&" "&INDEX(Evenimente!$C$2:$C$16203,MATCH(A6-0.000001,Evenimente!$A$2:$A$16203,1)+1)&" "&TEXT(HOUR(INDEX(Evenimente!$A$2:$A$16203,MATCH(A6-0.000001,Evenimente!$A$2:$A$16203,1)+1)),"00")&":"&TEXT(MINUTE(INDEX(Evenimente!$A$2:$A$16203,MATCH(A6-0.000001,Evenimente!$A$2:$A$16203,1)+1)),"00")&" UTC"&IF(INDEX(Evenimente!$A$2:$A$16203,MATCH(A6-0.000001,Evenimente!$A$2:$A$16203,1)+2)<A6+1,"; "&INDEX(Evenimente!$B$2:$B$16203,MATCH(A6-0.000001,Evenimente!$A$2:$A$16203,1)+2)&" "&INDEX(Evenimente!$C$2:$C$16203,MATCH(A6-0.000001,Evenimente!$A$2:$A$16203,1)+2)&" "&TEXT(HOUR(INDEX(Evenimente!$A$2:$A$16203,MATCH(A6-0.000001,Evenimente!$A$2:$A$16203,1)+2)),"00")&":"&TEXT(MINUTE(INDEX(Evenimente!$A$2:$A$16203,MATCH(A6-0.000001,Evenimente!$A$2:$A$16203,1)+2)),"00")&" UTC",""),""))
A7: =IF(B7="","",$B$3+B7-1) -> 46014 | B7: =IF(ROW()-4<=$E$2,ROW()-4,"") -> 3 | C7: =IF(B7="","",IF(B7<='Timp complet'!$B$60,INT((B7-1)/'Timp complet'!$B$58)+1,IF(B7='Timp complet'!$B$60+1,"Ziua anului","Ziua bisectă"))) -> 1 | D7: =IF(B7="","",IF(B7<='Timp complet'!$B$60,MOD(B7-1,'Timp complet'!$B$58)+1,"-")) -> 3 | E7: =IF(B7="","",IF(B7<='Timp complet'!$B$60,INDEX('Nume sanscrită'!$B$21:$B$27,MOD(B7-1,7)+1),"-")) -> Miercuri | F7: =IF(B7="","",INDEX('Nume sanscrită'!$B$21:$B$27,WEEKDAY(A7,2))) -> Marți | G7: =IF(B7="","",MIN('Timp complet'!$B$54,INT((B7-1)/'Timp complet'!$B$53)+1)) -> 1 | H7: =IF(B7="","",INDEX(Evenimente!$G$2:$G$1213,MATCH(A7+1,Evenimente!$F$2:$F$1213,1))) -> 1 | I7: =IF(B7="","",IF(INDEX(Evenimente!$A$2:$A$16203,MATCH(A7-0.000001,Evenimente!$A$2:$A$16203,1)+1)<A7+1,INDEX(Evenimente!$B$2:$B$16203,MATCH(A7-0.000001,Evenimente!$A$2:$A$16203,1)+1)&" "&INDEX(Evenimente!$C$2:$C$16203,MATCH(A7-0.000001,Evenimente!$A$2:$A$16203,1)+1)&" "&TEXT(HOUR(INDEX(Evenimente!$A$2:$A$16203,MATCH(A7-0.000001,Evenimente!$A$2:$A$16203,1)+1)),"00")&":"&TEXT(MINUTE(INDEX(Evenimente!$A$2:$A$16203,MATCH(A7-0.000001,Evenimente!$A$2:$A$16203,1)+1)),"00")&" UTC"&IF(INDEX(Evenimente!$A$2:$A$16203,MATCH(A7-0.000001,Evenimente!$A$2:$A$16203,1)+2)<A7+1,"; "&INDEX(Evenimente!$B$2:$B$16203,MATCH(A7-0.000001,Evenimente!$A$2:$A$16203,1)+2)&" "&INDEX(Evenimente!$C$2:$C$16203,MATCH(A7-0.000001,Evenimente!$A$2:$A$16203,1)+2)&" "&TEXT(HOUR(INDEX(Evenimente!$A$2:$A$16203,MATCH(A7-0.000001,Evenimente!$A$2:$A$16203,1)+2)),"00")&":"&TEXT(MINUTE(INDEX(Evenimente!$A$2:$A$16203,MATCH(A7-0.000001,Evenimente!$A$2:$A$16203,1)+2)),"00")&" UTC",""),""))
A8: =IF(B8="","",$B$3+B8-1) -> 46015 | B8: =IF(ROW()-4<=$E$2,ROW()-4,"") -> 4 | C8: =IF(B8="","",IF(B8<='Timp complet'!$B$60,INT((B8-1)/'Timp complet'!$B$58)+1,IF(B8='Timp complet'!$B$60+1,"Ziua anului","Ziua bisectă"))) -> 1 | D8: =IF(B8="","",IF(B8<='Timp complet'!$B$60,MOD(B8-1,'Timp complet'!$B$58)+1,"-")) -> 4 | E8: =IF(B8="","",IF(B8<='Timp complet'!$B$60,INDEX('Nume sanscrită'!$B$21:$B$27,MOD(B8-1,7)+1),"-")) -> Joi | F8: =IF(B8="","",INDEX('Nume sanscrită'!$B$21:$B$27,WEEKDAY(A8,2))) -> Miercuri | G8: =IF(B8="","",MIN('Timp complet'!$B$54,INT((B8-1)/'Timp complet'!$B$53)+1)) -> 1 | H8: =IF(B8="","",INDEX(Evenimente!$G$2:$G$1213,MATCH(A8+1,Evenimente!$F$2:$F$1213,1))) -> 1 | I8: =IF(B8="","",IF(INDEX(Evenimente!$A$2:$A$16203,MATCH(A8-0.000001,Evenimente!$A$2:$A$16203,1)+1)<A8+1,INDEX(Evenimente!$B$2:$B$16203,MATCH(A8-0.000001,Evenimente!$A$2:$A$16203,1)+1)&" "&INDEX(Evenimente!$C$2:$C$16203,MATCH(A8-0.000001,Evenimente!$A$2:$A$16203,1)+1)&" "&TEXT(HOUR(INDEX(Evenimente!$A$2:$A$16203,MATCH(A8-0.000001,Evenimente!$A$2:$A$16203,1)+1)),"00")&":"&TEXT(MINUTE(INDEX(Evenimente!$A$2:$A$16203,MATCH(A8-0.000001,Evenimente!$A$2:$A$16203,1)+1)),"00")&" UTC"&IF(INDEX(Evenimente!$A$2:$A$16203,MATCH(A8-0.000001,Evenimente!$A$2:$A$16203,1)+2)<A8+1,"; "&INDEX(Evenimente!$B$2:$B$16203,MATCH(A8-0.000001,Evenimente!$A$2:$A$16203,1)+2)&" "&INDEX(Evenimente!$C$2:$C$16203,MATCH(A8-0.000001,Evenimente!$A$2:$A$16203,1)+2)&" "&TEXT(HOUR(INDEX(Evenimente!$A$2:$A$16203,MATCH(A8-0.000001,Evenimente!$A$2:$A$16203,1)+2)),"00")&":"&TEXT(MINUTE(INDEX(Evenimente!$A$2:$A$16203,MATCH(A8-0.000001,Evenimente!$A$2:$A$16203,1)+2)),"00")&" UTC",""),""))
A9: =IF(B9="","",$B$3+B9-1) -> 46016 | B9: =IF(ROW()-4<=$E$2,ROW()-4,"") -> 5 | C9: =IF(B9="","",IF(B9<='Timp complet'!$B$60,INT((B9-1)/'Timp complet'!$B$58)+1,IF(B9='Timp complet'!$B$60+1,"Ziua anului","Ziua bisectă"))) -> 1 | D9: =IF(B9="","",IF(B9<='Timp complet'!$B$60,MOD(B9-1,'Timp complet'!$B$58)+1,"-")) -> 5 | E9: =IF(B9="","",IF(B9<='Timp complet'!$B$60,INDEX('Nume sanscrită'!$B$21:$B$27,MOD(B9-1,7)+1),"-")) -> Vineri | F9: =IF(B9="","",INDEX('Nume sanscrită'!$B$21:$B$27,WEEKDAY(A9,2))) -> Joi | G9: =IF(B9="","",MIN('Timp complet'!$B$54,INT((B9-1)/'Timp complet'!$B$53)+1)) -> 1 | H9: =IF(B9="","",INDEX(Evenimente!$G$2:$G$1213,MATCH(A9+1,Evenimente!$F$2:$F$1213,1))) -> 1 | I9: =IF(B9="","",IF(INDEX(Evenimente!$A$2:$A$16203,MATCH(A9-0.000001,Evenimente!$A$2:$A$16203,1)+1)<A9+1,INDEX(Evenimente!$B$2:$B$16203,MATCH(A9-0.000001,Evenimente!$A$2:$A$16203,1)+1)&" "&INDEX(Evenimente!$C$2:$C$16203,MATCH(A9-0.000001,Evenimente!$A$2:$A$16203,1)+1)&" "&TEXT(HOUR(INDEX(Evenimente!$A$2:$A$16203,MATCH(A9-0.000001,Evenimente!$A$2:$A$16203,1)+1)),"00")&":"&TEXT(MINUTE(INDEX(Evenimente!$A$2:$A$16203,MATCH(A9-0.000001,Evenimente!$A$2:$A$16203,1)+1)),"00")&" UTC"&IF(INDEX(Evenimente!$A$2:$A$16203,MATCH(A9-0.000001,Evenimente!$A$2:$A$16203,1)+2)<A9+1,"; "&INDEX(Evenimente!$B$2:$B$16203,MATCH(A9-0.000001,Evenimente!$A$2:$A$16203,1)+2)&" "&INDEX(Evenimente!$C$2:$C$16203,MATCH(A9-0.000001,Evenimente!$A$2:$A$16203,1)+2)&" "&TEXT(HOUR(INDEX(Evenimente!$A$2:$A$16203,MATCH(A9-0.000001,Evenimente!$A$2:$A$16203,1)+2)),"00")&":"&TEXT(MINUTE(INDEX(Evenimente!$A$2:$A$16203,MATCH(A9-0.000001,Evenimente!$A$2:$A$16203,1)+2)),"00")&" UTC",""),""))
A10: =IF(B10="","",$B$3+B10-1) -> 46017 | B10: =IF(ROW()-4<=$E$2,ROW()-4,"") -> 6 | C10: =IF(B10="","",IF(B10<='Timp complet'!$B$60,INT((B10-1)/'Timp complet'!$B$58)+1,IF(B10='Timp complet'!$B$60+1,"Ziua anului","Ziua bisectă"))) -> 1 | D10: =IF(B10="","",IF(B10<='Timp complet'!$B$60,MOD(B10-1,'Timp complet'!$B$58)+1,"-")) -> 6 | E10: =IF(B10="","",IF(B10<='Timp complet'!$B$60,INDEX('Nume sanscrită'!$B$21:$B$27,MOD(B10-1,7)+1),"-")) -> Sâmbătă | F10: =IF(B10="","",INDEX('Nume sanscrită'!$B$21:$B$27,WEEKDAY(A10,2))) -> Vineri | G10: =IF(B10="","",MIN('Timp complet'!$B$54,INT((B10-1)/'Timp complet'!$B$53)+1)) -> 2 | H10: =IF(B10="","",INDEX(Evenimente!$G$2:$G$1213,MATCH(A10+1,Evenimente!$F$2:$F$1213,1))) -> 1 | I10: =IF(B10="","",IF(INDEX(Evenimente!$A$2:$A$16203,MATCH(A10-0.000001,Evenimente!$A$2:$A$16203,1)+1)<A10+1,INDEX(Evenimente!$B$2:$B$16203,MATCH(A10-0.000001,Evenimente!$A$2:$A$16203,1)+1)&" "&INDEX(Evenimente!$C$2:$C$16203,MATCH(A10-0.000001,Evenimente!$A$2:$A$16203,1)+1)&" "&TEXT(HOUR(INDEX(Evenimente!$A$2:$A$16203,MATCH(A10-0.000001,Evenimente!$A$2:$A$16203,1)+1)),"00")&":"&TEXT(MINUTE(INDEX(Evenimente!$A$2:$A$16203,MATCH(A10-0.000001,Evenimente!$A$2:$A$16203,1)+1)),"00")&" UTC"&IF(INDEX(Evenimente!$A$2:$A$16203,MATCH(A10-0.000001,Evenimente!$A$2:$A$16203,1)+2)<A10+1,"; "&INDEX(Evenimente!$B$2:$B$16203,MATCH(A10-0.000001,Evenimente!$A$2:$A$16203,1)+2)&" "&INDEX(Evenimente!$C$2:$C$16203,MATCH(A10-0.000001,Evenimente!$A$2:$A$16203,1)+2)&" "&TEXT(HOUR(INDEX(Evenimente!$A$2:$A$16203,MATCH(A10-0.000001,Evenimente!$A$2:$A$16203,1)+2)),"00")&":"&TEXT(MINUTE(INDEX(Evenimente!$A$2:$A$16203,MATCH(A10-0.000001,Evenimente!$A$2:$A$16203,1)+2)),"00")&" UTC",""),""))
A11: =IF(B11="","",$B$3+B11-1) -> 46018 | B11: =IF(ROW()-4<=$E$2,ROW()-4,"") -> 7 | C11: =IF(B11="","",IF(B11<='Timp complet'!$B$60,INT((B11-1)/'Timp complet'!$B$58)+1,IF(B11='Timp complet'!$B$60+1,"Ziua anului","Ziua bisectă"))) -> 1 | D11: =IF(B11="","",IF(B11<='Timp complet'!$B$60,MOD(B11-1,'Timp complet'!$B$58)+1,"-")) -> 7 | E11: =IF(B11="","",IF(B11<='Timp complet'!$B$60,INDEX('Nume sanscrită'!$B$21:$B$27,MOD(B11-1,7)+1),"-")) -> Duminică | F11: =IF(B11="","",INDEX('Nume sanscrită'!$B$21:$B$27,WEEKDAY(A11,2))) -> Sâmbătă | G11: =IF(B11="","",MIN('Timp complet'!$B$54,INT((B11-1)/'Timp complet'!$B$53)+1)) -> 2 | H11: =IF(B11="","",INDEX(Evenimente!$G$2:$G$1213,MATCH(A11+1,Evenimente!$F$2:$F$1213,1))) -> 1 | I11: =IF(B11="","",IF(INDEX(Evenimente!$A$2:$A$16203,MATCH(A11-0.000001,Evenimente!$A$2:$A$16203,1)+1)<A11+1,INDEX(Evenimente!$B$2:$B$16203,MATCH(A11-0.000001,Evenimente!$A$2:$A$16203,1)+1)&" "&INDEX(Evenimente!$C$2:$C$16203,MATCH(A11-0.000001,Evenimente!$A$2:$A$16203,1)+1)&" "&TEXT(HOUR(INDEX(Evenimente!$A$2:$A$16203,MATCH(A11-0.000001,Evenimente!$A$2:$A$16203,1)+1)),"00")&":"&TEXT(MINUTE(INDEX(Evenimente!$A$2:$A$16203,MATCH(A11-0.000001,Evenimente!$A$2:$A$16203,1)+1)),"00")&" UTC"&IF(INDEX(Evenimente!$A$2:$A$16203,MATCH(A11-0.000001,Evenimente!$A$2:$A$16203,1)+2)<A11+1,"; "&INDEX(Evenimente!$B$2:$B$16203,MATCH(A11-0.000001,Evenimente!$A$2:$A$16203,1)+2)&" "&INDEX(Evenimente!$C$2:$C$16203,MATCH(A11-0.000001,Evenimente!$A$2:$A$16203,1)+2)&" "&TEXT(HOUR(INDEX(Evenimente!$A$2:$A$16203,MATCH(A11-0.000001,Evenimente!$A$2:$A$16203,1)+2)),"00")&":"&TEXT(MINUTE(INDEX(Evenimente!$A$2:$A$16203,MATCH(A11-0.000001,Evenimente!$A$2:$A$16203,1)+2)),"00")&" UTC",""),"")) -> ◐ primul pătrar 19:10 UTC
A12: =IF(B12="","",$B$3+B12-1) -> 46019 | B12: =IF(ROW()-4<=$E$2,ROW()-4,"") -> 8 | C12: =IF(B12="","",IF(B12<='Timp complet'!$B$60,INT((B12-1)/'Timp complet'!$B$58)+1,IF(B12='Timp complet'!$B$60+1,"Ziua anului","Ziua bisectă"))) -> 1 | D12: =IF(B12="","",IF(B12<='Timp complet'!$B$60,MOD(B12-1,'Timp complet'!$B$58)+1,"-")) -> 8 | E12: =IF(B12="","",IF(B12<='Timp complet'!$B$60,INDEX('Nume sanscrită'!$B$21:$B$27,MOD(B12-1,7)+1),"-")) -> Luni | F12: =IF(B12="","",INDEX('Nume sanscrită'!$B$21:$B$27,WEEKDAY(A12,2))) -> Duminică | G12: =IF(B12="","",MIN('Timp complet'!$B$54,INT((B12-1)/'Timp complet'!$B$53)+1)) -> 2 | H12: =IF(B12="","",INDEX(Evenimente!$G$2:$G$1213,MATCH(A12+1,Evenimente!$F$2:$F$1213,1))) -> 1 | I12: =IF(B12="","",IF(INDEX(Evenimente!$A$2:$A$16203,MATCH(A12-0.000001,Evenimente!$A$2:$A$16203,1)+1)<A12+1,INDEX(Evenimente!$B$2:$B$16203,MATCH(A12-0.000001,Evenimente!$A$2:$A$16203,1)+1)&" "&INDEX(Evenimente!$C$2:$C$16203,MATCH(A12-0.000001,Evenimente!$A$2:$A$16203,1)+1)&" "&TEXT(HOUR(INDEX(Evenimente!$A$2:$A$16203,MATCH(A12-0.000001,Evenimente!$A$2:$A$16203,1)+1)),"00")&":"&TEXT(MINUTE(INDEX(Evenimente!$A$2:$A$16203,MATCH(A12-0.000001,Evenimente!$A$2:$A$16203,1)+1)),"00")&" UTC"&IF(INDEX(Evenimente!$A$2:$A$16203,MATCH(A12-0.000001,Evenimente!$A$2:$A$16203,1)+2)<A12+1,"; "&INDEX(Evenimente!$B$2:$B$16203,MATCH(A12-0.000001,Evenimente!$A$2:$A$16203,1)+2)&" "&INDEX(Evenimente!$C$2:$C$16203,MATCH(A12-0.000001,Evenimente!$A$2:$A$16203,1)+2)&" "&TEXT(HOUR(INDEX(Evenimente!$A$2:$A$16203,MATCH(A12-0.000001,Evenimente!$A$2:$A$16203,1)+2)),"00")&":"&TEXT(MINUTE(INDEX(Evenimente!$A$2:$A$16203,MATCH(A12-0.000001,Evenimente!$A$2:$A$16203,1)+2)),"00")&" UTC",""),""))
A13: =IF(B13="","",$B$3+B13-1) -> 46020 | B13: =IF(ROW()-4<=$E$2,ROW()-4,"") -> 9 | C13: =IF(B13="","",IF(B13<='Timp complet'!$B$60,INT((B13-1)/'Timp complet'!$B$58)+1,IF(B13='Timp complet'!$B$60+1,"Ziua anului","Ziua bisectă"))) -> 1 | D13: =IF(B13="","",IF(B13<='Timp complet'!$B$60,MOD(B13-1,'Timp complet'!$B$58)+1,"-")) -> 9 | E13: =IF(B13="","",IF(B13<='Timp complet'!$B$60,INDEX('Nume sanscrită'!$B$21:$B$27,MOD(B13-1,7)+1),"-")) -> Marți | F13: =IF(B13="","",INDEX('Nume sanscrită'!$B$21:$B$27,WEEKDAY(A13,2))) -> Luni | G13: =IF(B13="","",MIN('Timp complet'!$B$54,INT((B13-1)/'Timp complet'!$B$53)+1)) -> 2 | H13: =IF(B13="","",INDEX(Evenimente!$G$2:$G$1213,MATCH(A13+1,Evenimente!$F$2:$F$1213,1))) -> 1 | I13: =IF(B13="","",IF(INDEX(Evenimente!$A$2:$A$16203,MATCH(A13-0.000001,Evenimente!$A$2:$A$16203,1)+1)<A13+1,INDEX(Evenimente!$B$2:$B$16203,MATCH(A13-0.000001,Evenimente!$A$2:$A$16203,1)+1)&" "&INDEX(Evenimente!$C$2:$C$16203,MATCH(A13-0.000001,Evenimente!$A$2:$A$16203,1)+1)&" "&TEXT(HOUR(INDEX(Evenimente!$A$2:$A$16203,MATCH(A13-0.000001,Evenimente!$A$2:$A$16203,1)+1)),"00")&":"&TEXT(MINUTE(INDEX(Evenimente!$A$2:$A$16203,MATCH(A13-0.000001,Evenimente!$A$2:$A$16203,1)+1)),"00")&" UTC"&IF(INDEX(Evenimente!$A$2:$A$16203,MATCH(A13-0.000001,Evenimente!$A$2:$A$16203,1)+2)<A13+1,"; "&INDEX(Evenimente!$B$2:$B$16203,MATCH(A13-0.000001,Evenimente!$A$2:$A$16203,1)+2)&" "&INDEX(Evenimente!$C$2:$C$16203,MATCH(A13-0.000001,Evenimente!$A$2:$A$16203,1)+2)&" "&TEXT(HOUR(INDEX(Evenimente!$A$2:$A$16203,MATCH(A13-0.000001,Evenimente!$A$2:$A$16203,1)+2)),"00")&":"&TEXT(MINUTE(INDEX(Evenimente!$A$2:$A$16203,MATCH(A13-0.000001,Evenimente!$A$2:$A$16203,1)+2)),"00")&" UTC",""),""))
A14: =IF(B14="","",$B$3+B14-1) -> 46021 | B14: =IF(ROW()-4<=$E$2,ROW()-4,"") -> 10 | C14: =IF(B14="","",IF(B14<='Timp complet'!$B$60,INT((B14-1)/'Timp complet'!$B$58)+1,IF(B14='Timp complet'!$B$60+1,"Ziua anului","Ziua bisectă"))) -> 1 | D14: =IF(B14="","",IF(B14<='Timp complet'!$B$60,MOD(B14-1,'Timp complet'!$B$58)+1,"-")) -> 10 | E14: =IF(B14="","",IF(B14<='Timp complet'!$B$60,INDEX('Nume sanscrită'!$B$21:$B$27,MOD(B14-1,7)+1),"-")) -> Miercuri | F14: =IF(B14="","",INDEX('Nume sanscrită'!$B$21:$B$27,WEEKDAY(A14,2))) -> Marți | G14: =IF(B14="","",MIN('Timp complet'!$B$54,INT((B14-1)/'Timp complet'!$B$53)+1)) -> 2 | H14: =IF(B14="","",INDEX(Evenimente!$G$2:$G$1213,MATCH(A14+1,Evenimente!$F$2:$F$1213,1))) -> 1 | I14: =IF(B14="","",IF(INDEX(Evenimente!$A$2:$A$16203,MATCH(A14-0.000001,Evenimente!$A$2:$A$16203,1)+1)<A14+1,INDEX(Evenimente!$B$2:$B$16203,MATCH(A14-0.000001,Evenimente!$A$2:$A$16203,1)+1)&" "&INDEX(Evenimente!$C$2:$C$16203,MATCH(A14-0.000001,Evenimente!$A$2:$A$16203,1)+1)&" "&TEXT(HOUR(INDEX(Evenimente!$A$2:$A$16203,MATCH(A14-0.000001,Evenimente!$A$2:$A$16203,1)+1)),"00")&":"&TEXT(MINUTE(INDEX(Evenimente!$A$2:$A$16203,MATCH(A14-0.000001,Evenimente!$A$2:$A$16203,1)+1)),"00")&" UTC"&IF(INDEX(Evenimente!$A$2:$A$16203,MATCH(A14-0.000001,Evenimente!$A$2:$A$16203,1)+2)<A14+1,"; "&INDEX(Evenimente!$B$2:$B$16203,MATCH(A14-0.000001,Evenimente!$A$2:$A$16203,1)+2)&" "&INDEX(Evenimente!$C$2:$C$16203,MATCH(A14-0.000001,Evenimente!$A$2:$A$16203,1)+2)&" "&TEXT(HOUR(INDEX(Evenimente!$A$2:$A$16203,MATCH(A14-0.000001,Evenimente!$A$2:$A$16203,1)+2)),"00")&":"&TEXT(MINUTE(INDEX(Evenimente!$A$2:$A$16203,MATCH(A14-0.000001,Evenimente!$A$2:$A$16203,1)+2)),"00")&" UTC",""),""))
A15: =IF(B15="","",$B$3+B15-1) -> 46022 | B15: =IF(ROW()-4<=$E$2,ROW()-4,"") -> 11 | C15: =IF(B15="","",IF(B15<='Timp complet'!$B$60,INT((B15-1)/'Timp complet'!$B$58)+1,IF(B15='Timp complet'!$B$60+1,"Ziua anului","Ziua bisectă"))) -> 1 | D15: =IF(B15="","",IF(B15<='Timp complet'!$B$60,MOD(B15-1,'Timp complet'!$B$58)+1,"-")) -> 11 | E15: =IF(B15="","",IF(B15<='Timp complet'!$B$60,INDEX('Nume sanscrită'!$B$21:$B$27,MOD(B15-1,7)+1),"-")) -> Joi | F15: =IF(B15="","",INDEX('Nume sanscrită'!$B$21:$B$27,WEEKDAY(A15,2))) -> Miercuri | G15: =IF(B15="","",MIN('Timp complet'!$B$54,INT((B15-1)/'Timp complet'!$B$53)+1)) -> 3 | H15: =IF(B15="","",INDEX(Evenimente!$G$2:$G$1213,MATCH(A15+1,Evenimente!$F$2:$F$1213,1))) -> 1 | I15: =IF(B15="","",IF(INDEX(Evenimente!$A$2:$A$16203,MATCH(A15-0.000001,Evenimente!$A$2:$A$16203,1)+1)<A15+1,INDEX(Evenimente!$B$2:$B$16203,MATCH(A15-0.000001,Evenimente!$A$2:$A$16203,1)+1)&" "&INDEX(Evenimente!$C$2:$C$16203,MATCH(A15-0.000001,Evenimente!$A$2:$A$16203,1)+1)&" "&TEXT(HOUR(INDEX(Evenimente!$A$2:$A$16203,MATCH(A15-0.000001,Evenimente!$A$2:$A$16203,1)+1)),"00")&":"&TEXT(MINUTE(INDEX(Evenimente!$A$2:$A$16203,MATCH(A15-0.000001,Evenimente!$A$2:$A$16203,1)+1)),"00")&" UTC"&IF(INDEX(Evenimente!$A$2:$A$16203,MATCH(A15-0.000001,Evenimente!$A$2:$A$16203,1)+2)<A15+1,"; "&INDEX(Evenimente!$B$2:$B$16203,MATCH(A15-0.000001,Evenimente!$A$2:$A$16203,1)+2)&" "&INDEX(Evenimente!$C$2:$C$16203,MATCH(A15-0.000001,Evenimente!$A$2:$A$16203,1)+2)&" "&TEXT(HOUR(INDEX(Evenimente!$A$2:$A$16203,MATCH(A15-0.000001,Evenimente!$A$2:$A$16203,1)+2)),"00")&":"&TEXT(MINUTE(INDEX(Evenimente!$A$2:$A$16203,MATCH(A15-0.000001,Evenimente!$A$2:$A$16203,1)+2)),"00")&" UTC",""),""))
A16: =IF(B16="","",$B$3+B16-1) -> 46023 | B16: =IF(ROW()-4<=$E$2,ROW()-4,"") -> 12 | C16: =IF(B16="","",IF(B16<='Timp complet'!$B$60,INT((B16-1)/'Timp complet'!$B$58)+1,IF(B16='Timp complet'!$B$60+1,"Ziua anului","Ziua bisectă"))) -> 1 | D16: =IF(B16="","",IF(B16<='Timp complet'!$B$60,MOD(B16-1,'Timp complet'!$B$58)+1,"-")) -> 12 | E16: =IF(B16="","",IF(B16<='Timp complet'!$B$60,INDEX('Nume sanscrită'!$B$21:$B$27,MOD(B16-1,7)+1),"-")) -> Vineri | F16: =IF(B16="","",INDEX('Nume sanscrită'!$B$21:$B$27,WEEKDAY(A16,2))) -> Joi | G16: =IF(B16="","",MIN('Timp complet'!$B$54,INT((B16-1)/'Timp complet'!$B$53)+1)) -> 3 | H16: =IF(B16="","",INDEX(Evenimente!$G$2:$G$1213,MATCH(A16+1,Evenimente!$F$2:$F$1213,1))) -> 1 | I16: =IF(B16="","",IF(INDEX(Evenimente!$A$2:$A$16203,MATCH(A16-0.000001,Evenimente!$A$2:$A$16203,1)+1)<A16+1,INDEX(Evenimente!$B$2:$B$16203,MATCH(A16-0.000001,Evenimente!$A$2:$A$16203,1)+1)&" "&INDEX(Evenimente!$C$2:$C$16203,MATCH(A16-0.000001,Evenimente!$A$2:$A$16203,1)+1)&" "&TEXT(HOUR(INDEX(Evenimente!$A$2:$A$16203,MATCH(A16-0.000001,Evenimente!$A$2:$A$16203,1)+1)),"00")&":"&TEXT(MINUTE(INDEX(Evenimente!$A$2:$A$16203,MATCH(A16-0.000001,Evenimente!$A$2:$A$16203,1)+1)),"00")&" UTC"&IF(INDEX(Evenimente!$A$2:$A$16203,MATCH(A16-0.000001,Evenimente!$A$2:$A$16203,1)+2)<A16+1,"; "&INDEX(Evenimente!$B$2:$B$16203,MATCH(A16-0.000001,Evenimente!$A$2:$A$16203,1)+2)&" "&INDEX(Evenimente!$C$2:$C$16203,MATCH(A16-0.000001,Evenimente!$A$2:$A$16203,1)+2)&" "&TEXT(HOUR(INDEX(Evenimente!$A$2:$A$16203,MATCH(A16-0.000001,Evenimente!$A$2:$A$16203,1)+2)),"00")&":"&TEXT(MINUTE(INDEX(Evenimente!$A$2:$A$16203,MATCH(A16-0.000001,Evenimente!$A$2:$A$16203,1)+2)),"00")&" UTC",""),""))
... A370: =IF(B370="","",$B$3+B370-1) | B370: =IF(ROW()-4<=$E$2,ROW()-4,"") | C370: =IF(B370="","",IF(B370<='Timp complet'!$B$60,INT((B370-1)/'Timp complet'!$B$58)+1,IF(B370='Timp complet'!$B$60+1,"Ziua anului","Ziua bisectă"))) | D370: =IF(B370="","",IF(B370<='Timp complet'!$B$60,MOD(B370-1,'Timp complet'!$B$58)+1,"-")) | E370: =IF(B370="","",IF(B370<='Timp complet'!$B$60,INDEX('Nume sanscrită'!$B$21:$B$27,MOD(B370-1,7)+1),"-")) | F370: =IF(B370="","",INDEX('Nume sanscrită'!$B$21:$B$27,WEEKDAY(A370,2))) | G370: =IF(B370="","",MIN('Timp complet'!$B$54,INT((B370-1)/'Timp complet'!$B$53)+1)) | H370: =IF(B370="","",INDEX(Evenimente!$G$2:$G$1213,MATCH(A370+1,Evenimente!$F$2:$F$1213,1))) | I370: =IF(B370="","",IF(INDEX(Evenimente!$A$2:$A$16203,MATCH(A370-0.000001,Evenimente!$A$2:$A$16203,1)+1)<A370+1,INDEX(Evenimente!$B$2:$B$16203,MATCH(A370-0.000001,Evenimente!$A$2:$A$16203,1)+1)&" "&INDEX(Evenimente!$C$2:$C$16203,MATCH(A370-0.000001,Evenimente!$A$2:$A$16203,1)+1)&" "&TEXT(HOUR(INDEX(Evenimente!$A$2:$A$16203,MATCH(A370-0.000001,Evenimente!$A$2:$A$16203,1)+1)),"00")&":"&TEXT(MINUTE(INDEX(Evenimente!$A$2:$A$16203,MATCH(A370-0.000001,Evenimente!$A$2:$A$16203,1)+1)),"00")&" UTC"&IF(INDEX(Evenimente!$A$2:$A$16203,MATCH(A370-0.000001,Evenimente!$A$2:$A$16203,1)+2)<A370+1,"; "&INDEX(Evenimente!$B$2:$B$16203,MATCH(A370-0.000001,Evenimente!$A$2:$A$16203,1)+2)&" "&INDEX(Evenimente!$C$2:$C$16203,MATCH(A370-0.000001,Evenimente!$A$2:$A$16203,1)+2)&" "&TEXT(HOUR(INDEX(Evenimente!$A$2:$A$16203,MATCH(A370-0.000001,Evenimente!$A$2:$A$16203,1)+2)),"00")&":"&TEXT(MINUTE(INDEX(Evenimente!$A$2:$A$16203,MATCH(A370-0.000001,Evenimente!$A$2:$A$16203,1)+2)),"00")&" UTC",""),""))

Sheet Calendar perete
A1: Calendar de perete: 13 luni × 28 de zile, anul începe la solstițiul din decembrie (nume în sanscrită, engleză și franceză, fazele Lunii)
A2: An gregorian | B2: 2026 | C2: Anul nou k | D2: =$J$2+IF(DATE($B$2,7,1)>=('Timp complet'!$B$45+'Timp complet'!$B$46*($J$2)+INT(($J$2)/'Timp complet'!$B$47)-INT(($J$2)/'Timp complet'!$B$48)),1,IF(DATE($B$2,7,1)<('Timp complet'!$B$45+'Timp complet'!$B$46*($J$2-1)+INT(($J$2-1)/'Timp complet'!$B$47)-INT(($J$2-1)/'Timp complet'!$B$48)),-1,0)) -> 15 | E2: Începe la | F2: =('Timp complet'!$B$45+'Timp complet'!$B$46*(D2-1)+INT((D2-1)/'Timp complet'!$B$47)-INT((D2-1)/'Timp complet'!$B$48)) -> 46012 | G2: Zile în an | H2: =('Timp complet'!$B$45+'Timp complet'!$B$46*(D2)+INT((D2)/'Timp complet'!$B$47)-INT((D2)/'Timp complet'!$B$48))-F2 -> 365 | I2: k estimat | J2: =INT((DATE($B$2,7,1)-'Timp complet'!$B$45)/'Timp complet'!$B$49)+1 -> 15
A3: ER · AE · era | B3: =ROUNDUP('Timp complet'!$B$51*(MOD($D$2-('Timp complet'!$B$52-YEAR('Timp complet'!$B$45)),'Timp complet'!$B$50)+1)/'Timp complet'!$B$50,0) -> 12 | C3: =MOD($D$2-('Timp complet'!$B$52-YEAR('Timp complet'!$B$45)),'Timp complet'!$B$50)-INT(($B$3-1)*'Timp complet'!$B$50/'Timp complet'!$B$51)+1 -> 1734 | D3: =INDEX(Ere!$B$5:$B$16,$B$3) & " · " & INDEX(Ere!$C$5:$C$16,$B$3) & " · " & INDEX(Ere!$D$5:$D$16,$B$3) -> Mīna · Pisces · Poissons | F3: Nume zile | G3: Tradiționale | I3: primul eveniment | J3: =MATCH($F$2-0.000001,Evenimente!$A$2:$A$16203,1) -> 6789
A4: Sus, mare: ziua din calendarul de 13 luni. Jos, mic: data gregoriană și fenomenele astronomice (UTC). Anul se alege prin anul gregorian care conține 1 iulie. Fiecare lună se tipărește pe o pagină A4 orizontală.
A5: ="Luna 1 · "&'Nume sanscrită'!F5&" · "&'Nume sanscrită'!E5&" मास" -> Luna 1 · Prathama māsa · प्रथम मास
A6: ='Nume EN-FR'!B5&" · "&'Nume EN-FR'!C5 -> First month · Premier mois
A7: ="ER "&$B$3&" ("&$D$3&") · AE "&TEXT($C$3,"0000")&" | gregorian: "&TEXT(DAY($F$2+0),"00")&"."&TEXT(MONTH($F$2+0),"00")&"."&YEAR($F$2+0)&" – "&TEXT(DAY($F$2+27),"00")&"."&TEXT(MONTH($F$2+27),"00")&"."&YEAR($F$2+27) -> ER 12 (Mīna · Pisces · Poissons) · AE 1734 | gregorian: 21.12.2025 – 17.01.2026
A8: ='Nume sanscrită'!B21&CHAR(10)&IF($G$3="Numerice",'Nume sanscrită'!G21,'Nume sanscrită'!C21)&CHAR(10)&IF($G$3="Numerice",'Nume EN-FR'!E21&" / "&'Nume EN-FR'!F21,'Nume EN-FR'!C21&" / "&'Nume EN-FR'!D21) -> Luni Somavāra Monday / lundi | B8: ='Nume sanscrită'!B22&CHAR(10)&IF($G$3="Numerice",'Nume sanscrită'!G22,'Nume sanscrită'!C22)&CHAR(10)&IF($G$3="Numerice",'Nume EN-FR'!E22&" / "&'Nume EN-FR'!F22,'Nume EN-FR'!C22&" / "&'Nume EN-FR'!D22) -> Marți Maṅgalavāra Tuesday / mardi | C8: ='Nume sanscrită'!B23&CHAR(10)&IF($G$3="Numerice",'Nume sanscrită'!G23,'Nume sanscrită'!C23)&CHAR(10)&IF($G$3="Numerice",'Nume EN-FR'!E23&" / "&'Nume EN-FR'!F23,'Nume EN-FR'!C23&" / "&'Nume EN-FR'!D23) -> Miercuri Budhavāra Wednesday / mercredi | D8: ='Nume sanscrită'!B24&CHAR(10)&IF($G$3="Numerice",'Nume sanscrită'!G24,'Nume sanscrită'!C24)&CHAR(10)&IF($G$3="Numerice",'Nume EN-FR'!E24&" / "&'Nume EN-FR'!F24,'Nume EN-FR'!C24&" / "&'Nume EN-FR'!D24) -> Joi Guruvāra Thursday / jeudi | E8: ='Nume sanscrită'!B25&CHAR(10)&IF($G$3="Numerice",'Nume sanscrită'!G25,'Nume sanscrită'!C25)&CHAR(10)&IF($G$3="Numerice",'Nume EN-FR'!E25&" / "&'Nume EN-FR'!F25,'Nume EN-FR'!C25&" / "&'Nume EN-FR'!D25) -> Vineri Śukravāra Friday / vendredi | F8: ='Nume sanscrită'!B26&CHAR(10)&IF($G$3="Numerice",'Nume sanscrită'!G26,'Nume sanscrită'!C26)&CHAR(10)&IF($G$3="Numerice",'Nume EN-FR'!E26&" / "&'Nume EN-FR'!F26,'Nume EN-FR'!C26&" / "&'Nume EN-FR'!D26) -> Sâmbătă Śanivāra Saturday / samedi | G8: ='Nume sanscrită'!B27&CHAR(10)&IF($G$3="Numerice",'Nume sanscrită'!G27,'Nume sanscrită'!C27)&CHAR(10)&IF($G$3="Numerice",'Nume EN-FR'!E27&" / "&'Nume EN-FR'!F27,'Nume EN-FR'!C27&" / "&'Nume EN-FR'!D27) -> Duminică Ravivāra Sunday / dimanche
A9: 1 | B9: 2 | C9: 3 | D9: 4 | E9: 5 | F9: 6 | G9: 7
A10: =DAY($F$2+0)&" "&CHOOSE(MONTH($F$2+0),"ian","feb","mar","apr","mai","iun","iul","aug","sep","oct","nov","dec")&IF(INDEX(Evenimente!$A$2:$A$16203,MATCH($F$2+0-0.000001,Evenimente!$A$2:$A$16203,1)+1)<$F$2+0+1," "&INDEX(Evenimente!$B$2:$B$16203,MATCH($F$2+0-0.000001,Evenimente!$A$2:$A$16203,1)+1)&IF(INDEX(Evenimente!$A$2:$A$16203,MATCH($F$2+0-0.000001,Evenimente!$A$2:$A$16203,1)+2)<$F$2+0+1," "&INDEX(Evenimente!$B$2:$B$16203,MATCH($F$2+0-0.000001,Evenimente!$A$2:$A$16203,1)+2),""),"") -> 21 dec ☀ | B10: =DAY($F$2+1)&" "&CHOOSE(MONTH($F$2+1),"ian","feb","mar","apr","mai","iun","iul","aug","sep","oct","nov","dec")&IF(INDEX(Evenimente!$A$2:$A$16203,MATCH($F$2+1-0.000001,Evenimente!$A$2:$A$16203,1)+1)<$F$2+1+1," "&INDEX(Evenimente!$B$2:$B$16203,MATCH($F$2+1-0.000001,Evenimente!$A$2:$A$16203,1)+1)&IF(INDEX(Evenimente!$A$2:$A$16203,MATCH($F$2+1-0.000001,Evenimente!$A$2:$A$16203,1)+2)<$F$2+1+1," "&INDEX(Evenimente!$B$2:$B$16203,MATCH($F$2+1-0.000001,Evenimente!$A$2:$A$16203,1)+2),""),"") -> 22 dec | C10: =DAY($F$2+2)&" "&CHOOSE(MONTH($F$2+2),"ian","feb","mar","apr","mai","iun","iul","aug","sep","oct","nov","dec")&IF(INDEX(Evenimente!$A$2:$A$16203,MATCH($F$2+2-0.000001,Evenimente!$A$2:$A$16203,1)+1)<$F$2+2+1," "&INDEX(Evenimente!$B$2:$B$16203,MATCH($F$2+2-0.000001,Evenimente!$A$2:$A$16203,1)+1)&IF(INDEX(Evenimente!$A$2:$A$16203,MATCH($F$2+2-0.000001,Evenimente!$A$2:$A$16203,1)+2)<$F$2+2+1," "&INDEX(Evenimente!$B$2:$B$16203,MATCH($F$2+2-0.000001,Evenimente!$A$2:$A$16203,1)+2),""),"") -> 23 dec | D10: =DAY($F$2+3)&" "&CHOOSE(MONTH($F$2+3),"ian","feb","mar","apr","mai","iun","iul","aug","sep","oct","nov","dec")&IF(INDEX(Evenimente!$A$2:$A$16203,MATCH($F$2+3-0.000001,Evenimente!$A$2:$A$16203,1)+1)<$F$2+3+1," "&INDEX(Evenimente!$B$2:$B$16203,MATCH($F$2+3-0.000001,Evenimente!$A$2:$A$16203,1)+1)&IF(INDEX(Evenimente!$A$2:$A$16203,MATCH($F$2+3-0.000001,Evenimente!$A$2:$A$16203,1)+2)<$F$2+3+1," "&INDEX(Evenimente!$B$2:$B$16203,MATCH($F$2+3-0.000001,Evenimente!$A$2:$A$16203,1)+2),""),"") -> 24 dec | E10: =DAY($F$2+4)&" "&CHOOSE(MONTH($F$2+4),"ian","feb","mar","apr","mai","iun","iul","aug","sep","oct","nov","dec")&IF(INDEX(Evenimente!$A$2:$A$16203,MATCH($F$2+4-0.000001,Evenimente!$A$2:$A$16203,1)+1)<$F$2+4+1," "&INDEX(Evenimente!$B$2:$B$16203,MATCH($F$2+4-0.000001,Evenimente!$A$2:$A$16203,1)+1)&IF(INDEX(Evenimente!$A$2:$A$16203,MATCH($F$2+4-0.000001,Evenimente!$A$2:$A$16203,1)+2)<$F$2+4+1," "&INDEX(Evenimente!$B$2:$B$16203,MATCH($F$2+4-0.000001,Evenimente!$A$2:$A$16203,1)+2),""),"") -> 25 dec | F10: =DAY($F$2+5)&" "&CHOOSE(MONTH($F$2+5),"ian","feb","mar","apr","mai","iun","iul","aug","sep","oct","nov","dec")&IF(INDEX(Evenimente!$A$2:$A$16203,MATCH($F$2+5-0.000001,Evenimente!$A$2:$A$16203,1)+1)<$F$2+5+1," "&INDEX(Evenimente!$B$2:$B$16203,MATCH($F$2+5-0.000001,Evenimente!$A$2:$A$16203,1)+1)&IF(INDEX(Evenimente!$A$2:$A$16203,MATCH($F$2+5-0.000001,Evenimente!$A$2:$A$16203,1)+2)<$F$2+5+1," "&INDEX(Evenimente!$B$2:$B$16203,MATCH($F$2+5-0.000001,Evenimente!$A$2:$A$16203,1)+2),""),"") -> 26 dec | G10: =DAY($F$2+6)&" "&CHOOSE(MONTH($F$2+6),"ian","feb","mar","apr","mai","iun","iul","aug","sep","oct","nov","dec")&IF(INDEX(Evenimente!$A$2:$A$16203,MATCH($F$2+6-0.000001,Evenimente!$A$2:$A$16203,1)+1)<$F$2+6+1," "&INDEX(Evenimente!$B$2:$B$16203,MATCH($F$2+6-0.000001,Evenimente!$A$2:$A$16203,1)+1)&IF(INDEX(Evenimente!$A$2:$A$16203,MATCH($F$2+6-0.000001,Evenimente!$A$2:$A$16203,1)+2)<$F$2+6+1," "&INDEX(Evenimente!$B$2:$B$16203,MATCH($F$2+6-0.000001,Evenimente!$A$2:$A$16203,1)+2),""),"") -> 27 dec ◐
A11: 8 | B11: 9 | C11: 10 | D11: 11 | E11: 12 | F11: 13 | G11: 14
A12: =DAY($F$2+7)&" "&CHOOSE(MONTH($F$2+7),"ian","feb","mar","apr","mai","iun","iul","aug","sep","oct","nov","dec")&IF(INDEX(Evenimente!$A$2:$A$16203,MATCH($F$2+7-0.000001,Evenimente!$A$2:$A$16203,1)+1)<$F$2+7+1," "&INDEX(Evenimente!$B$2:$B$16203,MATCH($F$2+7-0.000001,Evenimente!$A$2:$A$16203,1)+1)&IF(INDEX(Evenimente!$A$2:$A$16203,MATCH($F$2+7-0.000001,Evenimente!$A$2:$A$16203,1)+2)<$F$2+7+1," "&INDEX(Evenimente!$B$2:$B$16203,MATCH($F$2+7-0.000001,Evenimente!$A$2:$A$16203,1)+2),""),"") -> 28 dec | B12: =DAY($F$2+8)&" "&CHOOSE(MONTH($F$2+8),"ian","feb","mar","apr","mai","iun","iul","aug","sep","oct","nov","dec")&IF(INDEX(Evenimente!$A$2:$A$16203,MATCH($F$2+8-0.000001,Evenimente!$A$2:$A$16203,1)+1)<$F$2+8+1," "&INDEX(Evenimente!$B$2:$B$16203,MATCH($F$2+8-0.000001,Evenimente!$A$2:$A$16203,1)+1)&IF(INDEX(Evenimente!$A$2:$A$16203,MATCH($F$2+8-0.000001,Evenimente!$A$2:$A$16203,1)+2)<$F$2+8+1," "&INDEX(Evenimente!$B$2:$B$16203,MATCH($F$2+8-0.000001,Evenimente!$A$2:$A$16203,1)+2),""),"") -> 29 dec | C12: =DAY($F$2+9)&" "&CHOOSE(MONTH($F$2+9),"ian","feb","mar","apr","mai","iun","iul","aug","sep","oct","nov","dec")&IF(INDEX(Evenimente!$A$2:$A$16203,MATCH($F$2+9-0.000001,Evenimente!$A$2:$A$16203,1)+1)<$F$2+9+1," "&INDEX(Evenimente!$B$2:$B$16203,MATCH($F$2+9-0.000001,Evenimente!$A$2:$A$16203,1)+1)&IF(INDEX(Evenimente!$A$2:$A$16203,MATCH($F$2+9-0.000001,Evenimente!$A$2:$A$16203,1)+2)<$F$2+9+1," "&INDEX(Evenimente!$B$2:$B$16203,MATCH($F$2+9-0.000001,Evenimente!$A$2:$A$16203,1)+2),""),"") -> 30 dec | D12: =DAY($F$2+10)&" "&CHOOSE(MONTH($F$2+10),"ian","feb","mar","apr","mai","iun","iul","aug","sep","oct","nov","dec")&IF(INDEX(Evenimente!$A$2:$A$16203,MATCH($F$2+10-0.000001,Evenimente!$A$2:$A$16203,1)+1)<$F$2+10+1," "&INDEX(Evenimente!$B$2:$B$16203,MATCH($F$2+10-0.000001,Evenimente!$A$2:$A$16203,1)+1)&IF(INDEX(Evenimente!$A$2:$A$16203,MATCH($F$2+10-0.000001,Evenimente!$A$2:$A$16203,1)+2)<$F$2+10+1," "&INDEX(Evenimente!$B$2:$B$16203,MATCH($F$2+10-0.000001,Evenimente!$A$2:$A$16203,1)+2),""),"") -> 31 dec | E12: =DAY($F$2+11)&" "&CHOOSE(MONTH($F$2+11),"ian","feb","mar","apr","mai","iun","iul","aug","sep","oct","nov","dec")&IF(INDEX(Evenimente!$A$2:$A$16203,MATCH($F$2+11-0.000001,Evenimente!$A$2:$A$16203,1)+1)<$F$2+11+1," "&INDEX(Evenimente!$B$2:$B$16203,MATCH($F$2+11-0.000001,Evenimente!$A$2:$A$16203,1)+1)&IF(INDEX(Evenimente!$A$2:$A$16203,MATCH($F$2+11-0.000001,Evenimente!$A$2:$A$16203,1)+2)<$F$2+11+1," "&INDEX(Evenimente!$B$2:$B$16203,MATCH($F$2+11-0.000001,Evenimente!$A$2:$A$16203,1)+2),""),"") -> 1 ian | F12: =DAY($F$2+12)&" "&CHOOSE(MONTH($F$2+12),"ian","feb","mar","apr","mai","iun","iul","aug","sep","oct","nov","dec")&IF(INDEX(Evenimente!$A$2:$A$16203,MATCH($F$2+12-0.000001,Evenimente!$A$2:$A$16203,1)+1)<$F$2+12+1," "&INDEX(Evenimente!$B$2:$B$16203,MATCH($F$2+12-0.000001,Evenimente!$A$2:$A$16203,1)+1)&IF(INDEX(Evenimente!$A$2:$A$16203,MATCH($F$2+12-0.000001,Evenimente!$A$2:$A$16203,1)+2)<$F$2+12+1," "&INDEX(Evenimente!$B$2:$B$16203,MATCH($F$2+12-0.000001,Evenimente!$A$2:$A$16203,1)+2),""),"") -> 2 ian | G12: =DAY($F$2+13)&" "&CHOOSE(MONTH($F$2+13),"ian","feb","mar","apr","mai","iun","iul","aug","sep","oct","nov","dec")&IF(INDEX(Evenimente!$A$2:$A$16203,MATCH($F$2+13-0.000001,Evenimente!$A$2:$A$16203,1)+1)<$F$2+13+1," "&INDEX(Evenimente!$B$2:$B$16203,MATCH($F$2+13-0.000001,Evenimente!$A$2:$A$16203,1)+1)&IF(INDEX(Evenimente!$A$2:$A$16203,MATCH($F$2+13-0.000001,Evenimente!$A$2:$A$16203,1)+2)<$F$2+13+1," "&INDEX(Evenimente!$B$2:$B$16203,MATCH($F$2+13-0.000001,Evenimente!$A$2:$A$16203,1)+2),""),"") -> 3 ian ○
A13: 15 | B13: 16 | C13: 17 | D13: 18 | E13: 19 | F13: 20 | G13: 21
A14: =DAY($F$2+14)&" "&CHOOSE(MONTH($F$2+14),"ian","feb","mar","apr","mai","iun","iul","aug","sep","oct","nov","dec")&IF(INDEX(Evenimente!$A$2:$A$16203,MATCH($F$2+14-0.000001,Evenimente!$A$2:$A$16203,1)+1)<$F$2+14+1," "&INDEX(Evenimente!$B$2:$B$16203,MATCH($F$2+14-0.000001,Evenimente!$A$2:$A$16203,1)+1)&IF(INDEX(Evenimente!$A$2:$A$16203,MATCH($F$2+14-0.000001,Evenimente!$A$2:$A$16203,1)+2)<$F$2+14+1," "&INDEX(Evenimente!$B$2:$B$16203,MATCH($F$2+14-0.000001,Evenimente!$A$2:$A$16203,1)+2),""),"") -> 4 ian | B14: =DAY($F$2+15)&" "&CHOOSE(MONTH($F$2+15),"ian","feb","mar","apr","mai","iun","iul","aug","sep","oct","nov","dec")&IF(INDEX(Evenimente!$A$2:$A$16203,MATCH($F$2+15-0.000001,Evenimente!$A$2:$A$16203,1)+1)<$F$2+15+1," "&INDEX(Evenimente!$B$2:$B$16203,MATCH($F$2+15-0.000001,Evenimente!$A$2:$A$16203,1)+1)&IF(INDEX(Evenimente!$A$2:$A$16203,MATCH($F$2+15-0.000001,Evenimente!$A$2:$A$16203,1)+2)<$F$2+15+1," "&INDEX(Evenimente!$B$2:$B$16203,MATCH($F$2+15-0.000001,Evenimente!$A$2:$A$16203,1)+2),""),"") -> 5 ian | C14: =DAY($F$2+16)&" "&CHOOSE(MONTH($F$2+16),"ian","feb","mar","apr","mai","iun","iul","aug","sep","oct","nov","dec")&IF(INDEX(Evenimente!$A$2:$A$16203,MATCH($F$2+16-0.000001,Evenimente!$A$2:$A$16203,1)+1)<$F$2+16+1," "&INDEX(Evenimente!$B$2:$B$16203,MATCH($F$2+16-0.000001,Evenimente!$A$2:$A$16203,1)+1)&IF(INDEX(Evenimente!$A$2:$A$16203,MATCH($F$2+16-0.000001,Evenimente!$A$2:$A$16203,1)+2)<$F$2+16+1," "&INDEX(Evenimente!$B$2:$B$16203,MATCH($F$2+16-0.000001,Evenimente!$A$2:$A$16203,1)+2),""),"") -> 6 ian | D14: =DAY($F$2+17)&" "&CHOOSE(MONTH($F$2+17),"ian","feb","mar","apr","mai","iun","iul","aug","sep","oct","nov","dec")&IF(INDEX(Evenimente!$A$2:$A$16203,MATCH($F$2+17-0.000001,Evenimente!$A$2:$A$16203,1)+1)<$F$2+17+1," "&INDEX(Evenimente!$B$2:$B$16203,MATCH($F$2+17-0.000001,Evenimente!$A$2:$A$16203,1)+1)&IF(INDEX(Evenimente!$A$2:$A$16203,MATCH($F$2+17-0.000001,Evenimente!$A$2:$A$16203,1)+2)<$F$2+17+1," "&INDEX(Evenimente!$B$2:$B$16203,MATCH($F$2+17-0.000001,Evenimente!$A$2:$A$16203,1)+2),""),"") -> 7 ian | E14: =DAY($F$2+18)&" "&CHOOSE(MONTH($F$2+18),"ian","feb","mar","apr","mai","iun","iul","aug","sep","oct","nov","dec")&IF(INDEX(Evenimente!$A$2:$A$16203,MATCH($F$2+18-0.000001,Evenimente!$A$2:$A$16203,1)+1)<$F$2+18+1," "&INDEX(Evenimente!$B$2:$B$16203,MATCH($F$2+18-0.000001,Evenimente!$A$2:$A$16203,1)+1)&IF(INDEX(Evenimente!$A$2:$A$16203,MATCH($F$2+18-0.000001,Evenimente!$A$2:$A$16203,1)+2)<$F$2+18+1," "&INDEX(Evenimente!$B$2:$B$16203,MATCH($F$2+18-0.000001,Evenimente!$A$2:$A$16203,1)+2),""),"") -> 8 ian | F14: =DAY($F$2+19)&" "&CHOOSE(MONTH($F$2+19),"ian","feb","mar","apr","mai","iun","iul","aug","sep","oct","nov","dec")&IF(INDEX(Evenimente!$A$2:$A$16203,MATCH($F$2+19-0.000001,Evenimente!$A$2:$A$16203,1)+1)<$F$2+19+1," "&INDEX(Evenimente!$B$2:$B$16203,MATCH($F$2+19-0.000001,Evenimente!$A$2:$A$16203,1)+1)&IF(INDEX(Evenimente!$A$2:$A$16203,MATCH($F$2+19-0.000001,Evenimente!$A$2:$A$16203,1)+2)<$F$2+19+1," "&INDEX(Evenimente!$B$2:$B$16203,MATCH($F$2+19-0.000001,Evenimente!$A$2:$A$16203,1)+2),""),"") -> 9 ian | G14: =DAY($F$2+20)&" "&CHOOSE(MONTH($F$2+20),"ian","feb","mar","apr","mai","iun","iul","aug","sep","oct","nov","dec")&IF(INDEX(Evenimente!$A$2:$A$16203,MATCH($F$2+20-0.000001,Evenimente!$A$2:$A$16203,1)+1)<$F$2+20+1," "&INDEX(Evenimente!$B$2:$B$16203,MATCH($F$2+20-0.000001,Evenimente!$A$2:$A$16203,1)+1)&IF(INDEX(Evenimente!$A$2:$A$16203,MATCH($F$2+20-0.000001,Evenimente!$A$2:$A$16203,1)+2)<$F$2+20+1," "&INDEX(Evenimente!$B$2:$B$16203,MATCH($F$2+20-0.000001,Evenimente!$A$2:$A$16203,1)+2),""),"") -> 10 ian ◑
A15: 22 | B15: 23 | C15: 24 | D15: 25 | E15: 26 | F15: 27 | G15: 28
A16: =DAY($F$2+21)&" "&CHOOSE(MONTH($F$2+21),"ian","feb","mar","apr","mai","iun","iul","aug","sep","oct","nov","dec")&IF(INDEX(Evenimente!$A$2:$A$16203,MATCH($F$2+21-0.000001,Evenimente!$A$2:$A$16203,1)+1)<$F$2+21+1," "&INDEX(Evenimente!$B$2:$B$16203,MATCH($F$2+21-0.000001,Evenimente!$A$2:$A$16203,1)+1)&IF(INDEX(Evenimente!$A$2:$A$16203,MATCH($F$2+21-0.000001,Evenimente!$A$2:$A$16203,1)+2)<$F$2+21+1," "&INDEX(Evenimente!$B$2:$B$16203,MATCH($F$2+21-0.000001,Evenimente!$A$2:$A$16203,1)+2),""),"") -> 11 ian | B16: =DAY($F$2+22)&" "&CHOOSE(MONTH($F$2+22),"ian","feb","mar","apr","mai","iun","iul","aug","sep","oct","nov","dec")&IF(INDEX(Evenimente!$A$2:$A$16203,MATCH($F$2+22-0.000001,Evenimente!$A$2:$A$16203,1)+1)<$F$2+22+1," "&INDEX(Evenimente!$B$2:$B$16203,MATCH($F$2+22-0.000001,Evenimente!$A$2:$A$16203,1)+1)&IF(INDEX(Evenimente!$A$2:$A$16203,MATCH($F$2+22-0.000001,Evenimente!$A$2:$A$16203,1)+2)<$F$2+22+1," "&INDEX(Evenimente!$B$2:$B$16203,MATCH($F$2+22-0.000001,Evenimente!$A$2:$A$16203,1)+2),""),"") -> 12 ian | C16: =DAY($F$2+23)&" "&CHOOSE(MONTH($F$2+23),"ian","feb","mar","apr","mai","iun","iul","aug","sep","oct","nov","dec")&IF(INDEX(Evenimente!$A$2:$A$16203,MATCH($F$2+23-0.000001,Evenimente!$A$2:$A$16203,1)+1)<$F$2+23+1," "&INDEX(Evenimente!$B$2:$B$16203,MATCH($F$2+23-0.000001,Evenimente!$A$2:$A$16203,1)+1)&IF(INDEX(Evenimente!$A$2:$A$16203,MATCH($F$2+23-0.000001,Evenimente!$A$2:$A$16203,1)+2)<$F$2+23+1," "&INDEX(Evenimente!$B$2:$B$16203,MATCH($F$2+23-0.000001,Evenimente!$A$2:$A$16203,1)+2),""),"") -> 13 ian | D16: =DAY($F$2+24)&" "&CHOOSE(MONTH($F$2+24),"ian","feb","mar","apr","mai","iun","iul","aug","sep","oct","nov","dec")&IF(INDEX(Evenimente!$A$2:$A$16203,MATCH($F$2+24-0.000001,Evenimente!$A$2:$A$16203,1)+1)<$F$2+24+1," "&INDEX(Evenimente!$B$2:$B$16203,MATCH($F$2+24-0.000001,Evenimente!$A$2:$A$16203,1)+1)&IF(INDEX(Evenimente!$A$2:$A$16203,MATCH($F$2+24-0.000001,Evenimente!$A$2:$A$16203,1)+2)<$F$2+24+1," "&INDEX(Evenimente!$B$2:$B$16203,MATCH($F$2+24-0.000001,Evenimente!$A$2:$A$16203,1)+2),""),"") -> 14 ian | E16: =DAY($F$2+25)&" "&CHOOSE(MONTH($F$2+25),"ian","feb","mar","apr","mai","iun","iul","aug","sep","oct","nov","dec")&IF(INDEX(Evenimente!$A$2:$A$16203,MATCH($F$2+25-0.000001,Evenimente!$A$2:$A$16203,1)+1)<$F$2+25+1," "&INDEX(Evenimente!$B$2:$B$16203,MATCH($F$2+25-0.000001,Evenimente!$A$2:$A$16203,1)+1)&IF(INDEX(Evenimente!$A$2:$A$16203,MATCH($F$2+25-0.000001,Evenimente!$A$2:$A$16203,1)+2)<$F$2+25+1," "&INDEX(Evenimente!$B$2:$B$16203,MATCH($F$2+25-0.000001,Evenimente!$A$2:$A$16203,1)+2),""),"") -> 15 ian | F16: =DAY($F$2+26)&" "&CHOOSE(MONTH($F$2+26),"ian","feb","mar","apr","mai","iun","iul","aug","sep","oct","nov","dec")&IF(INDEX(Evenimente!$A$2:$A$16203,MATCH($F$2+26-0.000001,Evenimente!$A$2:$A$16203,1)+1)<$F$2+26+1," "&INDEX(Evenimente!$B$2:$B$16203,MATCH($F$2+26-0.000001,Evenimente!$A$2:$A$16203,1)+1)&IF(INDEX(Evenimente!$A$2:$A$16203,MATCH($F$2+26-0.000001,Evenimente!$A$2:$A$16203,1)+2)<$F$2+26+1," "&INDEX(Evenimente!$B$2:$B$16203,MATCH($F$2+26-0.000001,Evenimente!$A$2:$A$16203,1)+2),""),"") -> 16 ian | G16: =DAY($F$2+27)&" "&CHOOSE(MONTH($F$2+27),"ian","feb","mar","apr","mai","iun","iul","aug","sep","oct","nov","dec")&IF(INDEX(Evenimente!$A$2:$A$16203,MATCH($F$2+27-0.000001,Evenimente!$A$2:$A$16203,1)+1)<$F$2+27+1," "&INDEX(Evenimente!$B$2:$B$16203,MATCH($F$2+27-0.000001,Evenimente!$A$2:$A$16203,1)+1)&IF(INDEX(Evenimente!$A$2:$A$16203,MATCH($F$2+27-0.000001,Evenimente!$A$2:$A$16203,1)+2)<$F$2+27+1," "&INDEX(Evenimente!$B$2:$B$16203,MATCH($F$2+27-0.000001,Evenimente!$A$2:$A$16203,1)+2),""),"") -> 17 ian
A17: ● lună nouă ◐ primul pătrar ○ lună plină ◑ ultimul pătrar ☀ solstițiu / echinocțiu ⊗ eclipsă posibilă (fenomenele sunt în UTC)
A18: ="Luna 2 · "&'Nume sanscrită'!F6&" · "&'Nume sanscrită'!E6&" मास" -> Luna 2 · Dvitīya māsa · द्वितीय मास
A19: ='Nume EN-FR'!B6&" · "&'Nume EN-FR'!C6 -> Second month · Deuxième mois
A20: ="ER "&$B$3&" ("&$D$3&") · AE "&TEXT($C$3,"0000")&" | gregorian: "&TEXT(DAY($F$2+28),"00")&"."&TEXT(MONTH($F$2+28),"00")&"."&YEAR($F$2+28)&" – "&TEXT(DAY($F$2+55),"00")&"."&TEXT(MONTH($F$2+55),"00")&"."&YEAR($F$2+55) -> ER 12 (Mīna · Pisces · Poissons) · AE 1734 | gregorian: 18.01.2026 – 14.02.2026
A21: ='Nume sanscrită'!B21&CHAR(10)&IF($G$3="Numerice",'Nume sanscrită'!G21,'Nume sanscrită'!C21)&CHAR(10)&IF($G$3="Numerice",'Nume EN-FR'!E21&" / "&'Nume EN-FR'!F21,'Nume EN-FR'!C21&" / "&'Nume EN-FR'!D21) -> Luni Somavāra Monday / lundi | B21: ='Nume sanscrită'!B22&CHAR(10)&IF($G$3="Numerice",'Nume sanscrită'!G22,'Nume sanscrită'!C22)&CHAR(10)&IF($G$3="Numerice",'Nume EN-FR'!E22&" / "&'Nume EN-FR'!F22,'Nume EN-FR'!C22&" / "&'Nume EN-FR'!D22) -> Marți Maṅgalavāra Tuesday / mardi | C21: ='Nume sanscrită'!B23&CHAR(10)&IF($G$3="Numerice",'Nume sanscrită'!G23,'Nume sanscrită'!C23)&CHAR(10)&IF($G$3="Numerice",'Nume EN-FR'!E23&" / "&'Nume EN-FR'!F23,'Nume EN-FR'!C23&" / "&'Nume EN-FR'!D23) -> Miercuri Budhavāra Wednesday / mercredi | D21: ='Nume sanscrită'!B24&CHAR(10)&IF($G$3="Numerice",'Nume sanscrită'!G24,'Nume sanscrită'!C24)&CHAR(10)&IF($G$3="Numerice",'Nume EN-FR'!E24&" / "&'Nume EN-FR'!F24,'Nume EN-FR'!C24&" / "&'Nume EN-FR'!D24) -> Joi Guruvāra Thursday / jeudi | E21: ='Nume sanscrită'!B25&CHAR(10)&IF($G$3="Numerice",'Nume sanscrită'!G25,'Nume sanscrită'!C25)&CHAR(10)&IF($G$3="Numerice",'Nume EN-FR'!E25&" / "&'Nume EN-FR'!F25,'Nume EN-FR'!C25&" / "&'Nume EN-FR'!D25) -> Vineri Śukravāra Friday / vendredi | F21: ='Nume sanscrită'!B26&CHAR(10)&IF($G$3="Numerice",'Nume sanscrită'!G26,'Nume sanscrită'!C26)&CHAR(10)&IF($G$3="Numerice",'Nume EN-FR'!E26&" / "&'Nume EN-FR'!F26,'Nume EN-FR'!C26&" / "&'Nume EN-FR'!D26) -> Sâmbătă Śanivāra Saturday / samedi | G21: ='Nume sanscrită'!B27&CHAR(10)&IF($G$3="Numerice",'Nume sanscrită'!G27,'Nume sanscrită'!C27)&CHAR(10)&IF($G$3="Numerice",'Nume EN-FR'!E27&" / "&'Nume EN-FR'!F27,'Nume EN-FR'!C27&" / "&'Nume EN-FR'!D27) -> Duminică Ravivāra Sunday / dimanche
A22: 1 | B22: 2 | C22: 3 | D22: 4 | E22: 5 | F22: 6 | G22: 7
